<?xml version="1.0"?>
<!-- 
Sidenote: The mass and inertia are random values
TODO: Update mass and inertia to realistic values
-->
<robot xmlns:xacro="http://ros.org/wiki/xacro" name="motoman_hc10dtp">  
  <xacro:include filename="$(find motoman_resources)/urdf/common_materials.xacro" />
  <link name="base_link">
    <visual>
      <geometry>
        <mesh filename="file://$(find hc10dtp)/meshes/visual/base_link.dae" />
      </geometry>
      <xacro:material_yaskawa_blue />
    </visual>
    <collision>
      <geometry>
        <mesh filename="file://$(find hc10dtp)/meshes/collision/base_link.stl" />
      </geometry>
    </collision>
    <inertial>
      <origin xyz="0.0 0.0 0.0" rpy="0.0 0.0 0.0" />
      <mass value="10" />
      <inertia ixx="1e-3" ixy="0.0" ixz="0.0" iyy="1e-3" iyz="0.0" izz="1e-3" />
    </inertial>
  </link>
  <link name="link_1_s">
    <visual>
      <geometry>
        <mesh filename="file://$(find hc10dtp)/meshes/visual/link_1_s.dae" />
      </geometry>
      <xacro:material_yaskawa_blue />
    </visual>
    <collision>
      <geometry>
        <mesh filename="file://$(find hc10dtp)/meshes/collision/link_1_s.stl" />
      </geometry>
    </collision>
    <inertial>
      <origin xyz="0.0 0.0 0.0" rpy="0.0 0.0 0.0" />
      <mass value="10" />
      <inertia ixx="1e-3" ixy="0.0" ixz="0.0" iyy="1e-3" iyz="0.0" izz="1e-3" />
    </inertial>
  </link>
  <link name="link_2_l">
    <visual>
      <geometry>
        <mesh filename="file://$(find hc10dtp)/meshes/visual/link_2_l.dae" />
      </geometry>
      <xacro:material_yaskawa_blue />
    </visual>
    <collision>
      <geometry>
        <mesh filename="file://$(find hc10dtp)/meshes/collision/link_2_l.stl" />
      </geometry>
    </collision>
    <inertial>
      <origin xyz="0.0 0.0 0.0" rpy="0.0 0.0 0.0" />
      <mass value="10" />
      <inertia ixx="1e-3" ixy="0.0" ixz="0.0" iyy="1e-3" iyz="0.0" izz="1e-3" />
    </inertial>
  </link>
  <link name="link_3_u">
    <visual>
      <geometry>
        <mesh filename="file://$(find hc10dtp)/meshes/visual/link_3_u.dae" />
      </geometry>
      <xacro:material_yaskawa_blue />
    </visual>
    <collision>
      <geometry>
        <mesh filename="file://$(find hc10dtp)/meshes/collision/link_3_u.stl" />
      </geometry>
    </collision>
    <inertial>
      <origin xyz="0.0 0.0 0.0" rpy="0.0 0.0 0.0" />
      <mass value="6" />
      <inertia ixx="1e-3" ixy="0.0" ixz="0.0" iyy="1e-3" iyz="0.0" izz="1e-3" />
    </inertial>
  </link>
  <link name="link_4_r">
    <visual>
      <geometry>
        <mesh filename="file://$(find hc10dtp)/meshes/visual/link_4_r.dae" />
      </geometry>
      <xacro:material_yaskawa_blue />
    </visual>
    <collision>
      <geometry>
        <mesh filename="file://$(find hc10dtp)/meshes/collision/link_4_r.stl" />
      </geometry>
    </collision>
    <inertial>
      <origin xyz="0.0 0.0 0.0" rpy="0.0 0.0 0.0" />
      <mass value="4" />
      <inertia ixx="1e-3" ixy="0.0" ixz="0.0" iyy="1e-3" iyz="0.0" izz="1e-3" />
    </inertial>
  </link>
  <link name="link_5_b">
    <visual>
      <geometry>
        <mesh filename="file://$(find hc10dtp)/meshes/visual/link_5_b.dae" />
      </geometry>
      <xacro:material_yaskawa_blue />
    </visual>
    <collision>
      <geometry>
        <mesh filename="file://$(find hc10dtp)/meshes/collision/link_5_b.stl" />
      </geometry>
    </collision>
    <inertial>
      <origin xyz="0.0 0.0 0.0" rpy="0.0 0.0 0.0" />
      <mass value="3" />
      <inertia ixx="1e-3" ixy="0.0" ixz="0.0" iyy="1e-3" iyz="0.0" izz="1e-3" />
    </inertial>
  </link>
  <link name="link_6_t">
    <visual>
      <geometry>
        <mesh filename="file://$(find hc10dtp)/meshes/visual/link_6_t.dae" />
      </geometry>
      <xacro:material_yaskawa_blue />
    </visual>
    <collision>
      <geometry>
        <mesh filename="file://$(find hc10dtp)/meshes/collision/link_6_t.stl" />
      </geometry>
    </collision>
    <inertial>
      <origin xyz="0.0 0.0 0.0" rpy="0.0 0.0 0.0" />
      <mass value="3" />
      <inertia ixx="1e-3" ixy="0.0" ixz="0.0" iyy="1e-3" iyz="0.0" izz="1e-3" />
    </inertial>
  </link>

  <link name="tool0"/>
  <link name="eef_link"/>
  <!-- end of link list -->

  <!-- joint list -->
  <joint name="joint_1_s" type="revolute">
    <parent link="base_link" />
    <child link="link_1_s" />
    <origin xyz="0 0 0.275" rpy="0 0 0" />
    <axis xyz="0 0 1" />
    <limit lower="${radians(-180)}" upper="${radians(180)}" effort="368.48"
      velocity="${radians(130)}" />
  </joint>
  <joint name="joint_2_l" type="revolute">
    <parent link="link_1_s" />
    <child link="link_2_l" />
    <origin xyz="0 0 0" rpy="0 0 0" />
    <axis xyz="0 1 0" />
    <limit lower="${radians(-180)}" upper="${radians(180)}" effort="368.48"
      velocity="${radians(130)}" />
  </joint>
  <joint name="joint_3_u" type="revolute">
    <parent link="link_2_l" />
    <child link="link_3_u" />
    <origin xyz="0 0 0.700" rpy="0 0 0" />
    <axis xyz="0 -1 0" />
    <limit lower="${radians(-5)}" upper="${radians(355)}" effort="141.12"
      velocity="${radians(180)}" />
  </joint>
  <joint name="joint_4_r" type="revolute">
    <parent link="link_3_u" />
    <child link="link_4_r" />
    <origin xyz="0 0 -0.500" rpy="0 0 0" />
    <axis xyz="0 0 1" />
    <limit lower="${radians(-180)}" upper="${radians(180)}" effort="39.20"
      velocity="${radians(180)}" />
  </joint>
  <joint name="joint_5_b" type="revolute">
    <parent link="link_4_r" />
    <child link="link_5_b" />
    <origin xyz="0 0.162 0" rpy="0 0 0" />
    <axis xyz="0 -1 0" />
    <limit lower="${radians(-180)}" upper="${radians(180)}" effort="31.36"
      velocity="${radians(250)}" />
  </joint>
  <joint name="joint_6_t" type="revolute">
    <parent link="link_5_b" />
    <child link="link_6_t" />
    <origin xyz="0 0 0" rpy="0 0 0" />
    <axis xyz="0 0 1" />
    <limit lower="${radians(-180)}" upper="${radians(180)}" effort="31.36"
      velocity="${radians(250)}" />
  </joint>
  <joint name="joint_6_t-tool0" type="fixed">
    <origin xyz="0 0 -0.130" rpy="0 0 0" />
    <parent link="link_6_t" />
    <child link="tool0" />
  </joint>
  <!-- end of joint list -->

  <link name="world" />
  <joint name="virtual_joint" type="fixed">
    <parent link="world" />
    <child link="base_link" />
    <origin xyz="0 0 0" rpy="0 0 0" />
  </joint>
</robot>